[rospy.client][INFO] 2020-10-25 23:13:46,396: init_node, name[/rostopic_11144_1603692826377], pid[11144]
[xmlrpc][INFO] 2020-10-25 23:13:46,396: XML-RPC server binding to 0.0.0.0:0
[xmlrpc][INFO] 2020-10-25 23:13:46,397: Started XML-RPC server [http://freight1207:45381/]
[rospy.init][INFO] 2020-10-25 23:13:46,397: ROS Slave URI: [http://freight1207:45381/]
[rospy.impl.masterslave][INFO] 2020-10-25 23:13:46,397: _ready: http://freight1207:45381/
[rospy.registration][INFO] 2020-10-25 23:13:46,397: Registering with master node http://localhost:11311
[xmlrpc][INFO] 2020-10-25 23:13:46,397: xml rpc node: starting XML-RPC server
[rospy.init][INFO] 2020-10-25 23:13:46,497: registered with master
[rospy.rosout][INFO] 2020-10-25 23:13:46,497: initializing /rosout core topic
[rospy.rosout][INFO] 2020-10-25 23:13:46,499: connected to core topic /rosout
[rospy.simtime][INFO] 2020-10-25 23:13:46,500: /use_sim_time is not set, will not subscribe to simulated time [/clock] topic
[rospy.internal][INFO] 2020-10-25 23:13:46,719: topic[/rosout] adding connection to [/rosout], count 0
[rospy.internal][INFO] 2020-10-25 23:14:21,484: topic[/amcl_pose] adding connection to [http://freight1207:35562/], count 0
[rospy.internal][ERROR] 2020-10-25 23:15:48,698: Unable to initiate TCP/IP socket to freight1207:57281 (http://freight1207:35562/): Traceback (most recent call last):
  File "/opt/ros/indigo/lib/python2.7/dist-packages/rospy/impl/tcpros_base.py", line 557, in connect
    self.read_header()
  File "/opt/ros/indigo/lib/python2.7/dist-packages/rospy/impl/tcpros_base.py", line 619, in read_header
    self._validate_header(read_ros_handshake_header(sock, self.read_buff, self.protocol.buff_size))
  File "/opt/ros/indigo/lib/python2.7/dist-packages/rospy/impl/tcpros_base.py", line 580, in _validate_header
    raise TransportInitError("remote error reported: %s"%header['error'])
TransportInitError: remote error reported: received a connection for a nonexistent topic [/amcl_pose] from [TCPROS connection on port 57281 to [127.0.0.1:34108 on socket 9]] [/rostopic_11144_1603692826377].

[rospy.internal][WARNING] 2020-10-25 23:15:49,699: Unknown error initiating TCP/IP socket to freight1207:57281 (http://freight1207:35562/): Traceback (most recent call last):
  File "/opt/ros/indigo/lib/python2.7/dist-packages/rospy/impl/tcpros_base.py", line 555, in connect
    self.socket.connect((dest_addr, dest_port))
  File "/usr/lib/python2.7/socket.py", line 224, in meth
    return getattr(self._sock,name)(*args)
error: [Errno 111] Connection refused

[rospy.internal][INFO] 2020-10-25 23:15:49,699: topic[/amcl_pose] removing connection to http://freight1207:35562/
[rospy.internal][INFO] 2020-10-25 23:19:43,061: topic[/amcl_pose] adding connection to [http://freight1207:46399/], count 0
[rospy.internal][ERROR] 2020-10-25 23:21:12,951: Unable to initiate TCP/IP socket to freight1207:50898 (http://freight1207:46399/): Traceback (most recent call last):
  File "/opt/ros/indigo/lib/python2.7/dist-packages/rospy/impl/tcpros_base.py", line 557, in connect
    self.read_header()
  File "/opt/ros/indigo/lib/python2.7/dist-packages/rospy/impl/tcpros_base.py", line 619, in read_header
    self._validate_header(read_ros_handshake_header(sock, self.read_buff, self.protocol.buff_size))
  File "/opt/ros/indigo/lib/python2.7/dist-packages/rospy/impl/tcpros_base.py", line 580, in _validate_header
    raise TransportInitError("remote error reported: %s"%header['error'])
TransportInitError: remote error reported: received a connection for a nonexistent topic [/amcl_pose] from [TCPROS connection on port 50898 to [127.0.0.1:35433 on socket 9]] [/rostopic_11144_1603692826377].

[rospy.internal][WARNING] 2020-10-25 23:21:13,952: Unknown error initiating TCP/IP socket to freight1207:50898 (http://freight1207:46399/): Traceback (most recent call last):
  File "/opt/ros/indigo/lib/python2.7/dist-packages/rospy/impl/tcpros_base.py", line 555, in connect
    self.socket.connect((dest_addr, dest_port))
  File "/usr/lib/python2.7/socket.py", line 224, in meth
    return getattr(self._sock,name)(*args)
error: [Errno 111] Connection refused

[rospy.internal][INFO] 2020-10-25 23:21:13,952: topic[/amcl_pose] removing connection to http://freight1207:46399/
[rospy.internal][INFO] 2020-10-25 23:21:41,201: topic[/amcl_pose] adding connection to [http://freight1207:44504/], count 0
[rospy.internal][ERROR] 2020-10-25 23:23:29,735: Unable to initiate TCP/IP socket to freight1207:47272 (http://freight1207:44504/): Traceback (most recent call last):
  File "/opt/ros/indigo/lib/python2.7/dist-packages/rospy/impl/tcpros_base.py", line 557, in connect
    self.read_header()
  File "/opt/ros/indigo/lib/python2.7/dist-packages/rospy/impl/tcpros_base.py", line 619, in read_header
    self._validate_header(read_ros_handshake_header(sock, self.read_buff, self.protocol.buff_size))
  File "/opt/ros/indigo/lib/python2.7/dist-packages/rospy/impl/tcpros_base.py", line 580, in _validate_header
    raise TransportInitError("remote error reported: %s"%header['error'])
TransportInitError: remote error reported: received a connection for a nonexistent topic [/amcl_pose] from [TCPROS connection on port 47272 to [127.0.0.1:35795 on socket 9]] [/rostopic_11144_1603692826377].

[rospy.internal][WARNING] 2020-10-25 23:23:30,736: Unknown error initiating TCP/IP socket to freight1207:47272 (http://freight1207:44504/): Traceback (most recent call last):
  File "/opt/ros/indigo/lib/python2.7/dist-packages/rospy/impl/tcpros_base.py", line 555, in connect
    self.socket.connect((dest_addr, dest_port))
  File "/usr/lib/python2.7/socket.py", line 224, in meth
    return getattr(self._sock,name)(*args)
error: [Errno 111] Connection refused

[rospy.internal][INFO] 2020-10-25 23:23:30,737: topic[/amcl_pose] removing connection to http://freight1207:44504/
[rospy.internal][INFO] 2020-10-25 23:23:45,392: topic[/amcl_pose] adding connection to [http://freight1207:34671/], count 0
[rospy.internal][ERROR] 2020-10-25 23:24:44,862: Unable to initiate TCP/IP socket to freight1207:57459 (http://freight1207:34671/): Traceback (most recent call last):
  File "/opt/ros/indigo/lib/python2.7/dist-packages/rospy/impl/tcpros_base.py", line 557, in connect
    self.read_header()
  File "/opt/ros/indigo/lib/python2.7/dist-packages/rospy/impl/tcpros_base.py", line 619, in read_header
    self._validate_header(read_ros_handshake_header(sock, self.read_buff, self.protocol.buff_size))
  File "/opt/ros/indigo/lib/python2.7/dist-packages/rospy/impl/tcpros_base.py", line 580, in _validate_header
    raise TransportInitError("remote error reported: %s"%header['error'])
TransportInitError: remote error reported: received a connection for a nonexistent topic [/amcl_pose] from [TCPROS connection on port 57459 to [127.0.0.1:50510 on socket 9]] [/rostopic_11144_1603692826377].

[rospy.internal][WARNING] 2020-10-25 23:24:45,863: Unknown error initiating TCP/IP socket to freight1207:57459 (http://freight1207:34671/): Traceback (most recent call last):
  File "/opt/ros/indigo/lib/python2.7/dist-packages/rospy/impl/tcpros_base.py", line 555, in connect
    self.socket.connect((dest_addr, dest_port))
  File "/usr/lib/python2.7/socket.py", line 224, in meth
    return getattr(self._sock,name)(*args)
error: [Errno 111] Connection refused

[rospy.internal][INFO] 2020-10-25 23:24:45,864: topic[/amcl_pose] removing connection to http://freight1207:34671/
[rospy.internal][INFO] 2020-10-25 23:24:50,969: topic[/amcl_pose] adding connection to [http://freight1207:47466/], count 0
[rospy.internal][ERROR] 2020-10-25 23:29:09,072: Unable to initiate TCP/IP socket to freight1207:59315 (http://freight1207:47466/): Traceback (most recent call last):
  File "/opt/ros/indigo/lib/python2.7/dist-packages/rospy/impl/tcpros_base.py", line 557, in connect
    self.read_header()
  File "/opt/ros/indigo/lib/python2.7/dist-packages/rospy/impl/tcpros_base.py", line 619, in read_header
    self._validate_header(read_ros_handshake_header(sock, self.read_buff, self.protocol.buff_size))
  File "/opt/ros/indigo/lib/python2.7/dist-packages/rospy/impl/tcpros_base.py", line 580, in _validate_header
    raise TransportInitError("remote error reported: %s"%header['error'])
TransportInitError: remote error reported: received a connection for a nonexistent topic [/amcl_pose] from [TCPROS connection on port 59315 to [127.0.0.1:45902 on socket 9]] [/rostopic_11144_1603692826377].

[rospy.internal][WARNING] 2020-10-25 23:29:10,073: Unknown error initiating TCP/IP socket to freight1207:59315 (http://freight1207:47466/): Traceback (most recent call last):
  File "/opt/ros/indigo/lib/python2.7/dist-packages/rospy/impl/tcpros_base.py", line 555, in connect
    self.socket.connect((dest_addr, dest_port))
  File "/usr/lib/python2.7/socket.py", line 224, in meth
    return getattr(self._sock,name)(*args)
error: [Errno 111] Connection refused

[rospy.internal][INFO] 2020-10-25 23:29:10,074: topic[/amcl_pose] removing connection to http://freight1207:47466/
[rospy.core][INFO] 2020-10-25 23:29:15,496: signal_shutdown [signal-2]
[rospy.internal][INFO] 2020-10-25 23:29:15,498: topic[/rosout] removing connection to /rosout
[rospy.impl.masterslave][INFO] 2020-10-25 23:29:15,498: signal-2
[rospy.core][INFO] 2020-10-25 23:29:15,630: signal_shutdown [atexit]
